import {
  callWithRetry,
  callWithRetryAndTimeout,
  callWithTimeout,
} from "./call-wrappers";

describe("callWithTimeout", () => {
  const wait = async (milliseconds: number): Promise<string> => {
    return await new Promise((resolve) =>
      setTimeout(() => resolve("a"), milliseconds)
    );
  };

  const oneSecondCall = async (): Promise<string> => await wait(1000);

  describe("given a call that takes shorter than the timeout", () => {
    it("does not fail with a timeout error", async () => {
      // give it a second and a half to complete
      const result = await callWithTimeout(1500)(oneSecondCall)();
      expect(result).toBe("a");
    });
  });

  describe("given a call that takes longer than the timeout", () => {
    it("fails with a timeout error", async () => {
      try {
        // only give it a half a second to complete
        await callWithTimeout(500)(oneSecondCall)();
      } catch (error) {
        expect(error).toBeInstanceOf(Error);
        expect((error as Error).message).toBe("Operation timed out");
      }
      expect.hasAssertions();
    });
  });
});

describe("callWithRetry", () => {
  describe("given a function that succeeds the first time", () => {
    it("successfully retrieves the value", async () => {
      const result = await callWithRetry(3)(
        async () => await new Promise((resolve) => resolve("a"))
      )();
      expect(result).toBe("a");
    });
  });

  describe("given a function that fails on first call, then succeeds", () => {
    it("successfully retrieves the value if no error filter applied", async () => {
      let fail = true;

      const result = await callWithRetry(3)(
        async () =>
          await new Promise((resolve, reject) => {
            if (fail) {
              fail = false;
              reject(new Error("some failure"));
            } else {
              resolve("a");
            }
          })
      )();
      expect(result).toBe("a");
    });

    it("successfully retrieves the value if error filter matches the error thrown", async () => {
      let fail = true;

      const result = await callWithRetry(
        3,
        (error) => error.message === "some failure"
      )(
        async () =>
          await new Promise((resolve, reject) => {
            if (fail) {
              fail = false;
              reject(new Error("some failure"));
            } else {
              resolve("a");
            }
          })
      )();
      expect(result).toBe("a");
    });

    it("fails when error thrown that doesn't match the error filter", async () => {
      let fail = true;

      try {
        await callWithRetry(
          3,
          (error) => error.message === "some failure"
        )(
          async () =>
            await new Promise((resolve, reject) => {
              if (fail) {
                fail = false;
                reject(new Error("some other failure"));
              } else {
                resolve("a");
              }
            })
        )();
      } catch (error) {
        expect(error).toBeInstanceOf(Error);
        expect((error as Error).message).toBe("some other failure");
      }
      expect.hasAssertions();
    });
  });

  describe("given a function that fails consistently", () => {
    describe("when using the default retry option of always retrying", () => {
      it("fails to retrieve a value and throws the error from the last attempt", async () => {
        let attempt = 0;

        try {
          await callWithRetry(3)(
            async () =>
              await new Promise((resolve, reject) => {
                attempt++;
                reject(new Error(`failure on attempt ${attempt}`));
              })
          )();
        } catch (error) {
          expect(error).toBeInstanceOf(Error);
          expect((error as Error).message).toBe("failure on attempt 3");
        }
        expect.hasAssertions();
      });
    });
  });
});

describe("callWithRetryAndTimeout", () => {
  describe("given a function that times out then succeeds", () => {
    it("successfully retrieves the value", async () => {
      const wait = async (milliseconds: number): Promise<string> => {
        return await new Promise((resolve) =>
          setTimeout(() => resolve("a"), milliseconds)
        );
      };

      let delay = 2500;
      const slowFirstCall = async (): Promise<string> => {
        delay -= 1000;
        return await wait(delay);
      };

      const result = await callWithRetryAndTimeout(slowFirstCall)();
      expect(result).toBe("a");
    });
  });
});
